<?xml version="1.0"?>
<robot name="wheel" xmlns:xacro="http://www.ros.org/wiki/xacro">
  <!-- Wheels -->
  <xacro:property name="wheel_radius" value="0.0155"/>
  <xacro:property name="wheel_height" value="0.005"/>
  <xacro:property name="wheel_mass" value="2.5"/>

  <!-- <xacro:property name="base_x_origin_to_wheel_origin" value="0.25"/> -->
  <xacro:property name="base_x_origin_to_wheel_origin" value="0.0635"/>
  <!-- <xacro:property name="base_y_origin_to_wheel_origin" value="0.3"/> -->
  <xacro:property name="base_y_origin_to_wheel_origin" value="0.06"/>
  <!-- <xacro:property name="base_z_origin_to_wheel_origin" value="0.0"/> -->
  <xacro:property name="base_z_origin_to_wheel_origin" value="0.0267"/>

  <xacro:macro name="cylinder_inertia" params="m r h">
    <inertia ixx="${m*(3*r*r+h*h)/12}" ixy="0" ixz="0" iyy="${m*(3*r*r+h*h)/12}" iyz="0" izz="${m*r*r/2}"/>
  </xacro:macro>

  <xacro:macro name="wheel" params="lr parent translateX translateY translateZ flipY">
    <link name="${lr}_wheel_link">
      <visual>
        <!-- <origin xyz="${translateX} ${translateY} ${translateZ}" rpy="${flipY*PI/2} 0 0"/> -->
        <origin xyz="0 0 0" rpy="${flipY*PI/2} 0 0"/>
        <geometry>
          <cylinder length="${wheel_height}" radius="${wheel_radius}"/>
        </geometry>
        <material name="Black"/>
      </visual>
      <collision>
        <!-- <origin xyz="${translateX} ${translateY} ${translateZ}" rpy="${flipY*PI/2} 0 0"/> -->
        <origin xyz="0 0 0" rpy="${flipY*PI/2} 0 0"/>
        <geometry>
          <cylinder length="${wheel_height}" radius="${wheel_radius}"/>
        </geometry>
      </collision>
      <inertial>
        <mass value="${wheel_mass}"/>
        <!-- <origin xyz="${translateX} ${translateY} ${translateZ}"/> -->
        <origin xyz="0 0 0"/>
        <cylinder_inertia m="${wheel_mass}" r="${wheel_radius}" h="${wheel_height}"/>
      </inertial>
    </link>

    <gazebo reference="${lr}_wheel_link">
      <mu1 value="1.0"/>
      <mu2 value="1.0"/>
      <kp value="10000000.0"/>
      <kd value="1.0"/>
      <fdir1 value="1 0 0"/>
      <material>Gazebo/Black</material>
      <turnGravityOff>false</turnGravityOff>
    </gazebo>

    <joint name="${lr}_wheel_joint" type="continuous">
      <parent link="${parent}"/>
      <child link="${lr}_wheel_link"/>
      <!-- <origin xyz="0 0 0" rpy="0 0 0"/> -->
      <origin xyz="${translateX * base_x_origin_to_wheel_origin} ${translateY * base_y_origin_to_wheel_origin} ${translateZ * base_z_origin_to_wheel_origin}" rpy="0 0 0"/>
      <axis xyz="0 1 0" rpy="0 0 0"/>
      <limit effort="100" velocity="100"/>
      <joint_properties damping="0.0" friction="0.0"/>
    </joint>

    <!-- Transmission -->
    <transmission name="${lr}_wheel_joint_transmission">
      <type>transmission_interface/DifferentialTransmission</type>
      <joint name="${lr}_wheel_joint">
        <hardwareInterface>EffortJointInterface</hardwareInterface>
      </joint>
      <actuator name="${lr}_wheel_joint_motor">
        <hardwareInterface>EffortJointInterface</hardwareInterface>
        <mechanicalReduction>1</mechanicalReduction>
      </actuator>
    </transmission>
  </xacro:macro>

</robot>
