<?xml version="1.0" encoding="utf-8"?>
<robot xmlns:xacro="http://www.ros.org/wiki/xacro"
       name="leo_description">
  
  <link name="base_link">
    <visual>
      <origin xyz="0 0 0" rpy="0 0 0" />
      <geometry>
        <mesh filename="package://leo_description/models/base.dae"/>
      </geometry>
    </visual>
  </link>

  <xacro:macro name="wheel_link" params="name model"> 
    <link name="wheel_${name}_link">
      <visual>
        <origin xyz="0 0 0" rpy="0 0 0"/>
        <geometry>
          <mesh filename="package://leo_description/models/wheel_${model}.dae"/>
        </geometry>
      </visual>
    </link>
  </xacro:macro>

  <xacro:wheel_link name="FL" model="left"/>
  <xacro:wheel_link name="FR" model="right"/>
  <xacro:wheel_link name="RL" model="left"/>
  <xacro:wheel_link name="RR" model="right"/>
  
  <joint name="wheel_FL_joint" type="continuous">
    <origin xyz="0.1472 0.1114 -0.1353" rpy="0 0 ${pi}"/>
    <parent link="base_link"/>
    <child link="wheel_FL_link"/>
    <axis xyz="0 -1 0"/>
  </joint>

  <joint name="wheel_FR_joint" type="continuous">
    <origin xyz="0.1472 -0.1114 -0.1353" rpy="0 0 0"/>
    <parent link="base_link"/>
    <child link="wheel_FR_link"/>
    <axis xyz="0 1 0"/>
  </joint>

  <joint name="wheel_RL_joint" type="continuous">
    <origin xyz="-0.1419 0.1114 -0.1353" rpy="0 0 ${pi}"/>
    <parent link="base_link"/>
    <child link="wheel_RL_link"/>
    <axis xyz="0 -1 0"/>
  </joint>

  <joint name="wheel_RR_joint" type="continuous">
    <origin xyz="-0.1419 -0.1114 -0.1353" rpy="0 0 0"/>
    <parent link="base_link"/>
    <child link="wheel_RR_link"/>
    <axis xyz="0 1 0"/>
  </joint>

  <link name="camera_frame"/>

  <joint name="camera_joint" type="fixed">
      <origin xyz="0.0971 0 -0.0427" rpy="${-pi/2 - 0.2094} 0 ${-pi/2}"/>
      <parent link="base_link"/>
      <child link="camera_frame"/>
  </joint>

</robot>