<?xml version='1.0' encoding='utf-8'?>
<robot xmlns:xi="http://www.w3.org/2001/XInclude" name="room73b2-hitachi-fiesta-refrigerator_fixed">
  <macro name="room73b2-hitachi-fiesta-refrigerator_fixed" params="name parent *origin">
    <gazebo>
      <static>false</static>
    </gazebo>
    <link name="${name}_ROOT_link">
      <visual>
        <origin xyz="0 0 0" rpy="0 -0 0"/>
        <geometry>
          <mesh filename="package://eusurdf/textured_models/room73b2-hitachi-fiesta-refrigerator/meshes/ROOT_link_mesh.dae" scale="1 1 1"/>
        </geometry>
      </visual>
      <collision>
        <origin xyz="0 0 0" rpy="0 -0 0"/>
        <geometry>
          <mesh filename="package://eusurdf/textured_models/room73b2-hitachi-fiesta-refrigerator/meshes/ROOT_link_mesh.dae" scale="1 1 1"/>
        </geometry>
      </collision>
      <inertial>
        <mass value="0.001"/>
        <origin xyz="0 0 0" rpy="0 -0 0"/>
        <inertia ixx="1e-03" ixy="0" ixz="0" iyy="1e-03" iyz="0" izz="1e-03"/>
      </inertial>
    </link>
    <gazebo reference="${name}_ROOT_link">
      <mu1>0.9</mu1>
      <mu2>0.9</mu2>
    </gazebo>
    <link name="${name}_ROOM73B2-HITACHI-FIESTA-REFRIGERATOR-BODYSET7_link">
      <visual>
        <origin xyz="0.3 0.25 0.85" rpy="-1.57 -0 0"/>
        <geometry>
          <mesh filename="package://eusurdf/textured_models/room73b2-hitachi-fiesta-refrigerator/meshes/ROOM73B2-HITACHI-FIESTA-REFRIGERATOR-BODYSET7_link_mesh.dae" scale="1 1 1"/>
        </geometry>
      </visual>
      <collision>
        <origin xyz="0.3 0.245 0.85" rpy="-1.57 -0 0"/>
        <geometry>
          <mesh filename="package://eusurdf/textured_models/room73b2-hitachi-fiesta-refrigerator/meshes/ROOM73B2-HITACHI-FIESTA-REFRIGERATOR-BODYSET7_link_mesh.dae" scale="1 1 1"/>
        </geometry>
      </collision>
      <inertial>
        <mass value="0.001"/>
        <origin xyz="0 0 0" rpy="0 -0 0"/>
        <inertia ixx="1e-03" ixy="0" ixz="0" iyy="1e-03" iyz="0" izz="1e-03"/>
      </inertial>
    </link>
    <gazebo reference="${name}_ROOM73B2-HITACHI-FIESTA-REFRIGERATOR-BODYSET7_link">
      <mu1>0.9</mu1>
      <mu2>0.9</mu2>
    </gazebo>
    <link name="${name}_ROOM73B2-HITACHI-FIESTA-REFRIGERATOR-BODYSET6_link">
      <visual>
        <origin xyz="0.05 0 0.66" rpy="0 -0 0"/>
        <geometry>
          <mesh filename="package://eusurdf/textured_models/room73b2-hitachi-fiesta-refrigerator/meshes/ROOM73B2-HITACHI-FIESTA-REFRIGERATOR-BODYSET6_link_mesh.dae" scale="1 1 1"/>
        </geometry>
      </visual>
      <collision>
        <origin xyz="0.05 0 0.66" rpy="0 -0 0"/>
        <geometry>
          <mesh filename="package://eusurdf/textured_models/room73b2-hitachi-fiesta-refrigerator/meshes/ROOM73B2-HITACHI-FIESTA-REFRIGERATOR-BODYSET6_link_mesh.dae" scale="1 1 1"/>
        </geometry>
      </collision>
      <inertial>
        <mass value="0.001"/>
        <origin xyz="0 0 0" rpy="0 -0 0"/>
        <inertia ixx="1e-03" ixy="0" ixz="0" iyy="1e-03" iyz="0" izz="1e-03"/>
      </inertial>
    </link>
    <gazebo reference="${name}_ROOM73B2-HITACHI-FIESTA-REFRIGERATOR-BODYSET6_link">
      <mu1>0.9</mu1>
      <mu2>0.9</mu2>
    </gazebo>
    <link name="${name}_ROOM73B2-HITACHI-FIESTA-REFRIGERATOR-BODYSET5_link">
      <visual>
        <origin xyz="0.06 0 0.24" rpy="0 -0 0"/>
        <geometry>
          <mesh filename="package://eusurdf/textured_models/room73b2-hitachi-fiesta-refrigerator/meshes/ROOM73B2-HITACHI-FIESTA-REFRIGERATOR-BODYSET5_link_mesh.dae" scale="1 1 1"/>
        </geometry>
      </visual>
      <collision>
        <origin xyz="0.06 0 0.24" rpy="0 -0 0"/>
        <geometry>
          <mesh filename="package://eusurdf/textured_models/room73b2-hitachi-fiesta-refrigerator/meshes/ROOM73B2-HITACHI-FIESTA-REFRIGERATOR-BODYSET5_link_mesh.dae" scale="1 1 1"/>
        </geometry>
      </collision>
      <inertial>
        <mass value="0.001"/>
        <origin xyz="0 0 0" rpy="0 -0 0"/>
        <inertia ixx="1e-03" ixy="0" ixz="0" iyy="1e-03" iyz="0" izz="1e-03"/>
      </inertial>
    </link>
    <gazebo reference="${name}_ROOM73B2-HITACHI-FIESTA-REFRIGERATOR-BODYSET5_link">
      <mu1>0.9</mu1>
      <mu2>0.9</mu2>
    </gazebo>
    <link name="${name}_ROOM73B2-HITACHI-FIESTA-REFRIGERATOR-BODYSET4_link">
      <visual>
        <origin xyz="-0.095 0 1.275" rpy="0 -0 0"/>
        <geometry>
          <mesh filename="package://eusurdf/textured_models/room73b2-hitachi-fiesta-refrigerator/meshes/ROOM73B2-HITACHI-FIESTA-REFRIGERATOR-BODYSET4_link_mesh.dae" scale="1 1 1"/>
        </geometry>
      </visual>
      <collision>
        <origin xyz="-0.095 0 1.275" rpy="0 -0 0"/>
        <geometry>
          <mesh filename="package://eusurdf/textured_models/room73b2-hitachi-fiesta-refrigerator/meshes/ROOM73B2-HITACHI-FIESTA-REFRIGERATOR-BODYSET4_link_mesh.dae" scale="1 1 1"/>
        </geometry>
      </collision>
      <inertial>
        <mass value="0.001"/>
        <origin xyz="0 0 0" rpy="0 -0 0"/>
        <inertia ixx="1e-03" ixy="0" ixz="0" iyy="1e-03" iyz="0" izz="1e-03"/>
      </inertial>
    </link>
    <gazebo reference="${name}_ROOM73B2-HITACHI-FIESTA-REFRIGERATOR-BODYSET4_link">
      <mu1>0.9</mu1>
      <mu2>0.9</mu2>
    </gazebo>
    <link name="${name}_ROOM73B2-HITACHI-FIESTA-REFRIGERATOR-BODYSET3_link">
      <visual>
        <origin xyz="-0.095 0 1.085" rpy="0 -0 0"/>
        <geometry>
          <mesh filename="package://eusurdf/textured_models/room73b2-hitachi-fiesta-refrigerator/meshes/ROOM73B2-HITACHI-FIESTA-REFRIGERATOR-BODYSET3_link_mesh.dae" scale="1 1 1"/>
        </geometry>
      </visual>
      <collision>
        <origin xyz="-0.095 0 1.085" rpy="0 -0 0"/>
        <geometry>
          <mesh filename="package://eusurdf/textured_models/room73b2-hitachi-fiesta-refrigerator/meshes/ROOM73B2-HITACHI-FIESTA-REFRIGERATOR-BODYSET3_link_mesh.dae" scale="1 1 1"/>
        </geometry>
      </collision>
      <inertial>
        <mass value="0.001"/>
        <origin xyz="0 0 0" rpy="0 -0 0"/>
        <inertia ixx="1e-03" ixy="0" ixz="0" iyy="1e-03" iyz="0" izz="1e-03"/>
      </inertial>
    </link>
    <gazebo reference="${name}_ROOM73B2-HITACHI-FIESTA-REFRIGERATOR-BODYSET3_link">
      <mu1>0.9</mu1>
      <mu2>0.9</mu2>
    </gazebo>
    <link name="${name}_ROOM73B2-HITACHI-FIESTA-REFRIGERATOR-BODYSET2_link">
      <visual>
        <origin xyz="-0.095 0 0.935" rpy="0 -0 0"/>
        <geometry>
          <mesh filename="package://eusurdf/textured_models/room73b2-hitachi-fiesta-refrigerator/meshes/ROOM73B2-HITACHI-FIESTA-REFRIGERATOR-BODYSET2_link_mesh.dae" scale="1 1 1"/>
        </geometry>
      </visual>
      <collision>
        <origin xyz="-0.095 0 0.935" rpy="0 -0 0"/>
        <geometry>
          <mesh filename="package://eusurdf/textured_models/room73b2-hitachi-fiesta-refrigerator/meshes/ROOM73B2-HITACHI-FIESTA-REFRIGERATOR-BODYSET2_link_mesh.dae" scale="1 1 1"/>
        </geometry>
      </collision>
      <inertial>
        <mass value="0.001"/>
        <origin xyz="0 0 0" rpy="0 -0 0"/>
        <inertia ixx="1e-03" ixy="0" ixz="0" iyy="1e-03" iyz="0" izz="1e-03"/>
      </inertial>
    </link>
    <gazebo reference="${name}_ROOM73B2-HITACHI-FIESTA-REFRIGERATOR-BODYSET2_link">
      <mu1>0.9</mu1>
      <mu2>0.9</mu2>
    </gazebo>
    <joint name="${name}_root_parent_joint" type="fixed">
      <parent link="${parent}"/>
      <child link="${name}_world"/>
      <insert_block name="origin"/>
    </joint>
    <joint name="${name}_DOOR1" type="revolute">
      <parent link="${name}_ROOT_link"/>
      <child link="${name}_ROOM73B2-HITACHI-FIESTA-REFRIGERATOR-BODYSET7_link"/>
      <origin xyz="0.3 0.245 0.85" rpy="0 -0 0 "/>
      <axis xyz="0 0 1"/>
      <limit lower="0" upper="1.5708" effort="100" velocity="0.5"/>
      <dynamics damping="0.2" friction="0"/>
    </joint>
    <transmission type="pr2_mechanism_model/SimpleTransmission" name="${name}_DOOR1_trans">
      <actuator name="${name}_DOOR1_motor"/>
      <joint name="${name}_DOOR1"/>
      <mechanicalReduction>1</mechanicalReduction>
    </transmission>
    <gazebo reference="${name}_DOOR1">
      <cfmDamping>0.4</cfmDamping>
    </gazebo>
    <joint name="${name}_DRAWER1" type="prismatic">
      <parent link="${name}_ROOT_link"/>
      <child link="${name}_ROOM73B2-HITACHI-FIESTA-REFRIGERATOR-BODYSET6_link"/>
      <origin xyz="0.05 0 0.66" rpy="0 -0 0 "/>
      <axis xyz="1 0 0"/>
      <limit lower="0" upper="0.55" effort="100" velocity="0.01"/>
      <dynamics damping="0.2" friction="0"/>
    </joint>
    <transmission type="pr2_mechanism_model/SimpleTransmission" name="${name}_DRAWER1_trans">
      <actuator name="${name}_DRAWER1_motor"/>
      <joint name="${name}_DRAWER1"/>
      <mechanicalReduction>1</mechanicalReduction>
    </transmission>
    <gazebo reference="${name}_DRAWER1">
      <cfmDamping>0.4</cfmDamping>
    </gazebo>
    <joint name="${name}_DRAWER2" type="prismatic">
      <parent link="${name}_ROOT_link"/>
      <child link="${name}_ROOM73B2-HITACHI-FIESTA-REFRIGERATOR-BODYSET5_link"/>
      <origin xyz="0.06 0 0.24" rpy="0 -0 0 "/>
      <axis xyz="1 0 0"/>
      <limit lower="0" upper="0.55" effort="100" velocity="0.01"/>
      <dynamics damping="0.2" friction="0"/>
    </joint>
    <transmission type="pr2_mechanism_model/SimpleTransmission" name="${name}_DRAWER2_trans">
      <actuator name="${name}_DRAWER2_motor"/>
      <joint name="${name}_DRAWER2"/>
      <mechanicalReduction>1</mechanicalReduction>
    </transmission>
    <gazebo reference="${name}_DRAWER2">
      <cfmDamping>0.4</cfmDamping>
    </gazebo>
    <joint name="${name}_SHELF1" type="prismatic">
      <parent link="${name}_ROOT_link"/>
      <child link="${name}_ROOM73B2-HITACHI-FIESTA-REFRIGERATOR-BODYSET4_link"/>
      <origin xyz="-0.095 0 1.275" rpy="0 -0 0 "/>
      <axis xyz="1 0 0"/>
      <limit lower="0" upper="0.3" effort="100" velocity="0.01"/>
      <dynamics damping="0.2" friction="0"/>
    </joint>
    <transmission type="pr2_mechanism_model/SimpleTransmission" name="${name}_SHELF1_trans">
      <actuator name="${name}_SHELF1_motor"/>
      <joint name="${name}_SHELF1"/>
      <mechanicalReduction>1</mechanicalReduction>
    </transmission>
    <gazebo reference="${name}_SHELF1">
      <cfmDamping>0.4</cfmDamping>
    </gazebo>
    <joint name="${name}_SHELF2" type="prismatic">
      <parent link="${name}_ROOT_link"/>
      <child link="${name}_ROOM73B2-HITACHI-FIESTA-REFRIGERATOR-BODYSET3_link"/>
      <origin xyz="-0.095 0 1.085" rpy="0 -0 0 "/>
      <axis xyz="1 0 0"/>
      <limit lower="0" upper="0.3" effort="100" velocity="0.01"/>
      <dynamics damping="0.2" friction="0"/>
    </joint>
    <transmission type="pr2_mechanism_model/SimpleTransmission" name="${name}_SHELF2_trans">
      <actuator name="${name}_SHELF2_motor"/>
      <joint name="${name}_SHELF2"/>
      <mechanicalReduction>1</mechanicalReduction>
    </transmission>
    <gazebo reference="${name}_SHELF2">
      <cfmDamping>0.4</cfmDamping>
    </gazebo>
    <joint name="${name}_SHELF3" type="prismatic">
      <parent link="${name}_ROOT_link"/>
      <child link="${name}_ROOM73B2-HITACHI-FIESTA-REFRIGERATOR-BODYSET2_link"/>
      <origin xyz="-0.095 0 0.935" rpy="0 -0 0 "/>
      <axis xyz="1 0 0"/>
      <limit lower="0" upper="0.3" effort="100" velocity="0.01"/>
      <dynamics damping="0.2" friction="0"/>
    </joint>
    <transmission type="pr2_mechanism_model/SimpleTransmission" name="${name}_SHELF3_trans">
      <actuator name="${name}_SHELF3_motor"/>
      <joint name="${name}_SHELF3"/>
      <mechanicalReduction>1</mechanicalReduction>
    </transmission>
    <gazebo reference="${name}_SHELF3">
      <cfmDamping>0.4</cfmDamping>
    </gazebo>
    <!-- Used for fixing robot to Gazebo 'base_link' -->
    <link name="${name}_world"/>
    <joint name="${name}_fixed" type="fixed">
      <parent link="${name}_world"/>
      <child link="${name}_ROOT_link"/>
    </joint>
  </macro>
</robot>
